<sdf version='1.7'>
  <world name='default'>
    <light name='sun' type='directional'>
      <cast_shadows>1</cast_shadows>
      <pose>0 0 10 0 -0 0</pose>
      <diffuse>0.8 0.8 0.8 1</diffuse>
      <specular>0.2 0.2 0.2 1</specular>
      <attenuation>
        <range>1000</range>
        <constant>0.9</constant>
        <linear>0.01</linear>
        <quadratic>0.001</quadratic>
      </attenuation>
      <direction>-0.5 0.1 -0.9</direction>
      <spot>
        <inner_angle>0</inner_angle>
        <outer_angle>0</outer_angle>
        <falloff>0</falloff>
      </spot>
    </light>
    <model name='ground_plane'>
      <static>1</static>
      <link name='link'>
        <collision name='collision'>
          <geometry>
            <plane>
              <normal>0 0 1</normal>
              <size>100 100</size>
            </plane>
          </geometry>
          <surface>
            <contact>
              <collide_bitmask>65535</collide_bitmask>
              <ode/>
            </contact>
            <friction>
              <ode>
                <mu>100</mu>
                <mu2>50</mu2>
              </ode>
              <torsional>
                <ode/>
              </torsional>
            </friction>
            <bounce/>
          </surface>
          <max_contacts>10</max_contacts>
        </collision>
        <visual name='visual'>
          <cast_shadows>0</cast_shadows>
          <geometry>
            <plane>
              <normal>0 0 1</normal>
              <size>100 100</size>
            </plane>
          </geometry>
          <material>
            <script>
              <uri>file://media/materials/scripts/gazebo.material</uri>
              <name>Gazebo/Grey</name>
            </script>
          </material>
        </visual>
        <self_collide>0</self_collide>
        <enable_wind>0</enable_wind>
        <kinematic>0</kinematic>
      </link>
    </model>
    <gravity>0 0 -9.8</gravity>
    <magnetic_field>6e-06 2.3e-05 -4.2e-05</magnetic_field>
    <atmosphere type='adiabatic'/>
    <physics type='ode'>
      <max_step_size>0.001</max_step_size>
      <real_time_factor>1</real_time_factor>
      <real_time_update_rate>1000</real_time_update_rate>
    </physics>
    <scene>
      <ambient>0.4 0.4 0.4 1</ambient>
      <background>0.7 0.7 0.7 1</background>
      <shadows>1</shadows>
    </scene>
    <audio>
      <device>default</device>
    </audio>
    <wind/>
    <spherical_coordinates>
      <surface_model>EARTH_WGS84</surface_model>
      <latitude_deg>0</latitude_deg>
      <longitude_deg>0</longitude_deg>
      <elevation>0</elevation>
      <heading_deg>0</heading_deg>
    </spherical_coordinates>
    <model name='my_bot'>
      <link name='base_link'>
        <inertial>
          <pose>0 0 0.02 0 -0 0</pose>
          <mass>10</mass>
          <inertia>
            <ixx>0.209667</ixx>
            <ixy>0</ixy>
            <ixz>0</ixz>
            <iyy>0.209667</iyy>
            <iyz>0</iyz>
            <izz>0.416667</izz>
          </inertia>
        </inertial>
        <collision name='base_link_fixed_joint_lump__stand_link_collision'>
          <pose>0 0 0.02 0 -0 0</pose>
          <geometry>
            <box>
              <size>0.5 0.5 0.04</size>
            </box>
          </geometry>
          <surface>
            <contact>
              <ode/>
            </contact>
            <friction>
              <ode>
                <mu>50</mu>
                <mu2>50</mu2>
              </ode>
              <torsional>
                <ode/>
              </torsional>
            </friction>
            <bounce/>
          </surface>
          <max_contacts>10</max_contacts>
        </collision>
        <visual name='base_link_fixed_joint_lump__stand_link_visual'>
          <pose>0 0 0.02 0 -0 0</pose>
          <geometry>
            <box>
              <size>0.5 0.5 0.04</size>
            </box>
          </geometry>
          <material>
            <script>
              <name>Gazebo/Red</name>
              <uri>file://media/materials/scripts/gazebo.material</uri>
            </script>
          </material>
        </visual>
        <self_collide>0</self_collide>
        <enable_wind>0</enable_wind>
        <kinematic>0</kinematic>
      </link>
      <joint name='lleg1_ax1_joint' type='revolute'>
        <pose relative_to='base_link'>0.22 0.22 0.12 0 -0 0</pose>
        <parent>base_link</parent>
        <child>lleg1_ax1_link</child>
        <axis>
          <xyz>0 0 1</xyz>
          <limit>
            <lower>-1.5708</lower>
            <upper>1.5708</upper>
            <effort>30</effort>
            <velocity>1</velocity>
          </limit>
          <dynamics>
            <damping>10</damping>
            <friction>50</friction>
            <spring_reference>0</spring_reference>
            <spring_stiffness>0</spring_stiffness>
          </dynamics>
        </axis>
      </joint>
      <link name='lleg1_ax1_link'>
        <pose relative_to='lleg1_ax1_joint'>0 0 0 0 -0 0</pose>
        <inertial>
          <pose>0 0 0 0 -0 0</pose>
          <mass>5</mass>
          <inertia>
            <ixx>0.00483333</ixx>
            <ixy>0</ixy>
            <ixz>0</ixz>
            <iyy>0.00483333</iyy>
            <iyz>0</iyz>
            <izz>0.00133333</izz>
          </inertia>
        </inertial>
        <collision name='lleg1_ax1_link_collision'>
          <pose>0 0 -0.03 0 -0 0</pose>
          <geometry>
            <box>
              <size>0.04 0.04 0.1</size>
            </box>
          </geometry>
          <surface>
            <contact>
              <ode/>
            </contact>
            <friction>
              <ode>
                <mu>50</mu>
                <mu2>50</mu2>
              </ode>
              <torsional>
                <ode/>
              </torsional>
            </friction>
            <bounce/>
          </surface>
          <max_contacts>10</max_contacts>
        </collision>
        <visual name='lleg1_ax1_link_visual'>
          <pose>0 0 -0.03 0 -0 0</pose>
          <geometry>
            <box>
              <size>0.04 0.04 0.1</size>
            </box>
          </geometry>
          <material>
            <script>
              <name>Gazebo/Black</name>
              <uri>file://media/materials/scripts/gazebo.material</uri>
            </script>
          </material>
        </visual>
        <self_collide>0</self_collide>
        <enable_wind>0</enable_wind>
        <kinematic>0</kinematic>
      </link>
      <joint name='lleg1_ax2_joint' type='revolute'>
        <pose relative_to='lleg1_ax1_link'>0 0.04 0 0 -0 0</pose>
        <parent>lleg1_ax1_link</parent>
        <child>lleg1_ax2_link</child>
        <axis>
          <xyz>0 1 0</xyz>
          <limit>
            <lower>-1.5708</lower>
            <upper>1.5708</upper>
            <effort>30</effort>
            <velocity>1</velocity>
          </limit>
          <dynamics>
            <damping>10</damping>
            <friction>50</friction>
            <spring_reference>0</spring_reference>
            <spring_stiffness>0</spring_stiffness>
          </dynamics>
        </axis>
      </joint>
      <link name='lleg1_ax2_link'>
        <pose relative_to='lleg1_ax2_joint'>0 0 0 0 -0 0</pose>
        <inertial>
          <pose>0 0 0 0 -0 0</pose>
          <mass>5</mass>
          <inertia>
            <ixx>0.0673333</ixx>
            <ixy>0</ixy>
            <ixz>0</ixz>
            <iyy>0.0673333</iyy>
            <iyz>0</iyz>
            <izz>0.00133333</izz>
          </inertia>
        </inertial>
        <collision name='lleg1_ax2_link_collision'>
          <pose>0 0 0.18 0 -0 0</pose>
          <geometry>
            <box>
              <size>0.04 0.04 0.4</size>
            </box>
          </geometry>
          <surface>
            <contact>
              <ode/>
            </contact>
            <friction>
              <ode>
                <mu>50</mu>
                <mu2>50</mu2>
              </ode>
              <torsional>
                <ode/>
              </torsional>
            </friction>
            <bounce/>
          </surface>
          <max_contacts>10</max_contacts>
        </collision>
        <visual name='lleg1_ax2_link_visual'>
          <pose>0 0 0.18 0 -0 0</pose>
          <geometry>
            <box>
              <size>0.04 0.04 0.4</size>
            </box>
          </geometry>
          <material>
            <script>
              <name>Gazebo/Red</name>
              <uri>file://media/materials/scripts/gazebo.material</uri>
            </script>
          </material>
        </visual>
        <self_collide>0</self_collide>
        <enable_wind>0</enable_wind>
        <kinematic>0</kinematic>
      </link>
      <joint name='lleg1_ax3_joint' type='revolute'>
        <pose relative_to='lleg1_ax2_link'>0 0 0.36 0 -0 0</pose>
        <parent>lleg1_ax2_link</parent>
        <child>lleg1_ax3_link</child>
        <axis>
          <xyz>0 1 0</xyz>
          <limit>
            <lower>-3.14159</lower>
            <upper>3.14159</upper>
            <effort>30</effort>
            <velocity>1</velocity>
          </limit>
          <dynamics>
            <damping>10</damping>
            <friction>50</friction>
            <spring_reference>0</spring_reference>
            <spring_stiffness>0</spring_stiffness>
          </dynamics>
        </axis>
      </joint>
      <link name='lleg1_ax3_link'>
        <pose relative_to='lleg1_ax3_joint'>0 0 0 0 -0 0</pose>
        <inertial>
          <pose>0 0 0 0 -0 0</pose>
          <mass>5</mass>
          <inertia>
            <ixx>0.0673333</ixx>
            <ixy>0</ixy>
            <ixz>0</ixz>
            <iyy>0.0673333</iyy>
            <iyz>0</iyz>
            <izz>0.00133333</izz>
          </inertia>
        </inertial>
        <collision name='lleg1_ax3_link_collision'>
          <pose>0 -0.04 0.18 0 -0 0</pose>
          <geometry>
            <box>
              <size>0.04 0.04 0.4</size>
            </box>
          </geometry>
          <surface>
            <contact>
              <ode/>
            </contact>
            <friction>
              <ode>
                <mu>50</mu>
                <mu2>50</mu2>
                <fdir1>1 0 0</fdir1>
              </ode>
              <torsional>
                <ode/>
              </torsional>
            </friction>
            <bounce/>
          </surface>
          <max_contacts>10</max_contacts>
        </collision>
        <collision name='lleg1_ax3_link_collision_1'>
          <pose>0 -0.04 0.38 0 -0 0</pose>
          <geometry>
            <sphere>
              <radius>0.04</radius>
            </sphere>
          </geometry>
          <surface>
            <contact>
              <ode/>
            </contact>
            <friction>
              <ode>
                <mu>50</mu>
                <mu2>50</mu2>
                <fdir1>1 0 0</fdir1>
              </ode>
              <torsional>
                <ode/>
              </torsional>
            </friction>
            <bounce/>
          </surface>
          <max_contacts>10</max_contacts>
        </collision>
        <visual name='lleg1_ax3_link_visual'>
          <pose>0 -0.04 0.18 0 -0 0</pose>
          <geometry>
            <box>
              <size>0.04 0.04 0.4</size>
            </box>
          </geometry>
          <material>
            <script>
              <name>Gazebo/Black</name>
              <uri>file://media/materials/scripts/gazebo.material</uri>
            </script>
          </material>
        </visual>
        <visual name='lleg1_ax3_link_visual_1'>
          <pose>0 -0.04 0.38 0 -0 0</pose>
          <geometry>
            <sphere>
              <radius>0.04</radius>
            </sphere>
          </geometry>
          <material>
            <script>
              <name>Gazebo/Black</name>
              <uri>file://media/materials/scripts/gazebo.material</uri>
            </script>
          </material>
        </visual>
        <self_collide>0</self_collide>
        <enable_wind>0</enable_wind>
        <kinematic>0</kinematic>
      </link>
      <joint name='lleg2_ax1_joint' type='revolute'>
        <pose relative_to='base_link'>0.22 -0.22 0.12 0 -0 0</pose>
        <parent>base_link</parent>
        <child>lleg2_ax1_link</child>
        <axis>
          <xyz>0 0 1</xyz>
          <limit>
            <lower>-1.5708</lower>
            <upper>1.5708</upper>
            <effort>30</effort>
            <velocity>1</velocity>
          </limit>
          <dynamics>
            <damping>10</damping>
            <friction>50</friction>
            <spring_reference>0</spring_reference>
            <spring_stiffness>0</spring_stiffness>
          </dynamics>
        </axis>
      </joint>
      <link name='lleg2_ax1_link'>
        <pose relative_to='lleg2_ax1_joint'>0 0 0 0 -0 0</pose>
        <inertial>
          <pose>0 0 0 0 -0 0</pose>
          <mass>5</mass>
          <inertia>
            <ixx>0.00483333</ixx>
            <ixy>0</ixy>
            <ixz>0</ixz>
            <iyy>0.00483333</iyy>
            <iyz>0</iyz>
            <izz>0.00133333</izz>
          </inertia>
        </inertial>
        <collision name='lleg2_ax1_link_collision'>
          <pose>0 0 -0.03 0 -0 0</pose>
          <geometry>
            <box>
              <size>0.04 0.04 0.1</size>
            </box>
          </geometry>
          <surface>
            <contact>
              <ode/>
            </contact>
            <friction>
              <ode>
                <mu>50</mu>
                <mu2>50</mu2>
              </ode>
              <torsional>
                <ode/>
              </torsional>
            </friction>
            <bounce/>
          </surface>
          <max_contacts>10</max_contacts>
        </collision>
        <visual name='lleg2_ax1_link_visual'>
          <pose>0 0 -0.03 0 -0 0</pose>
          <geometry>
            <box>
              <size>0.04 0.04 0.1</size>
            </box>
          </geometry>
          <material>
            <script>
              <name>Gazebo/Black</name>
              <uri>file://media/materials/scripts/gazebo.material</uri>
            </script>
          </material>
        </visual>
        <self_collide>0</self_collide>
        <enable_wind>0</enable_wind>
        <kinematic>0</kinematic>
      </link>
      <joint name='lleg2_ax2_joint' type='revolute'>
        <pose relative_to='lleg2_ax1_link'>0 0.04 0 0 -0 0</pose>
        <parent>lleg2_ax1_link</parent>
        <child>lleg2_ax2_link</child>
        <axis>
          <xyz>0 1 0</xyz>
          <limit>
            <lower>-1.5708</lower>
            <upper>1.5708</upper>
            <effort>30</effort>
            <velocity>1</velocity>
          </limit>
          <dynamics>
            <damping>10</damping>
            <friction>50</friction>
            <spring_reference>0</spring_reference>
            <spring_stiffness>0</spring_stiffness>
          </dynamics>
        </axis>
      </joint>
      <link name='lleg2_ax2_link'>
        <pose relative_to='lleg2_ax2_joint'>0 0 0 0 -0 0</pose>
        <inertial>
          <pose>0 0 0 0 -0 0</pose>
          <mass>5</mass>
          <inertia>
            <ixx>0.0673333</ixx>
            <ixy>0</ixy>
            <ixz>0</ixz>
            <iyy>0.0673333</iyy>
            <iyz>0</iyz>
            <izz>0.00133333</izz>
          </inertia>
        </inertial>
        <collision name='lleg2_ax2_link_collision'>
          <pose>0 0 0.18 0 -0 0</pose>
          <geometry>
            <box>
              <size>0.04 0.04 0.4</size>
            </box>
          </geometry>
          <surface>
            <contact>
              <ode/>
            </contact>
            <friction>
              <ode>
                <mu>50</mu>
                <mu2>50</mu2>
              </ode>
              <torsional>
                <ode/>
              </torsional>
            </friction>
            <bounce/>
          </surface>
          <max_contacts>10</max_contacts>
        </collision>
        <visual name='lleg2_ax2_link_visual'>
          <pose>0 0 0.18 0 -0 0</pose>
          <geometry>
            <box>
              <size>0.04 0.04 0.4</size>
            </box>
          </geometry>
          <material>
            <script>
              <name>Gazebo/Red</name>
              <uri>file://media/materials/scripts/gazebo.material</uri>
            </script>
          </material>
        </visual>
        <self_collide>0</self_collide>
        <enable_wind>0</enable_wind>
        <kinematic>0</kinematic>
      </link>
      <joint name='lleg2_ax3_joint' type='revolute'>
        <pose relative_to='lleg2_ax2_link'>0 0 0.36 0 -0 0</pose>
        <parent>lleg2_ax2_link</parent>
        <child>lleg2_ax3_link</child>
        <axis>
          <xyz>0 1 0</xyz>
          <limit>
            <lower>-3.14159</lower>
            <upper>3.14159</upper>
            <effort>30</effort>
            <velocity>1</velocity>
          </limit>
          <dynamics>
            <damping>10</damping>
            <friction>50</friction>
            <spring_reference>0</spring_reference>
            <spring_stiffness>0</spring_stiffness>
          </dynamics>
        </axis>
      </joint>
      <link name='lleg2_ax3_link'>
        <pose relative_to='lleg2_ax3_joint'>0 0 0 0 -0 0</pose>
        <inertial>
          <pose>0 0 0 0 -0 0</pose>
          <mass>5</mass>
          <inertia>
            <ixx>0.0673333</ixx>
            <ixy>0</ixy>
            <ixz>0</ixz>
            <iyy>0.0673333</iyy>
            <iyz>0</iyz>
            <izz>0.00133333</izz>
          </inertia>
        </inertial>
        <collision name='lleg2_ax3_link_collision'>
          <pose>0 -0.04 0.18 0 -0 0</pose>
          <geometry>
            <box>
              <size>0.04 0.04 0.4</size>
            </box>
          </geometry>
          <surface>
            <contact>
              <ode/>
            </contact>
            <friction>
              <ode>
                <mu>50</mu>
                <mu2>50</mu2>
                <fdir1>1 0 0</fdir1>
              </ode>
              <torsional>
                <ode/>
              </torsional>
            </friction>
            <bounce/>
          </surface>
          <max_contacts>10</max_contacts>
        </collision>
        <collision name='lleg2_ax3_link_collision_1'>
          <pose>0 -0.04 0.38 0 -0 0</pose>
          <geometry>
            <sphere>
              <radius>0.04</radius>
            </sphere>
          </geometry>
          <surface>
            <contact>
              <ode/>
            </contact>
            <friction>
              <ode>
                <mu>50</mu>
                <mu2>50</mu2>
                <fdir1>1 0 0</fdir1>
              </ode>
              <torsional>
                <ode/>
              </torsional>
            </friction>
            <bounce/>
          </surface>
          <max_contacts>10</max_contacts>
        </collision>
        <visual name='lleg2_ax3_link_visual'>
          <pose>0 -0.04 0.18 0 -0 0</pose>
          <geometry>
            <box>
              <size>0.04 0.04 0.4</size>
            </box>
          </geometry>
          <material>
            <script>
              <name>Gazebo/Black</name>
              <uri>file://media/materials/scripts/gazebo.material</uri>
            </script>
          </material>
        </visual>
        <visual name='lleg2_ax3_link_visual_1'>
          <pose>0 -0.04 0.38 0 -0 0</pose>
          <geometry>
            <sphere>
              <radius>0.04</radius>
            </sphere>
          </geometry>
          <material>
            <script>
              <name>Gazebo/Black</name>
              <uri>file://media/materials/scripts/gazebo.material</uri>
            </script>
          </material>
        </visual>
        <self_collide>0</self_collide>
        <enable_wind>0</enable_wind>
        <kinematic>0</kinematic>
      </link>
      <joint name='rleg1_ax1_joint' type='revolute'>
        <pose relative_to='base_link'>-0.22 0.22 0.12 0 -0 0</pose>
        <parent>base_link</parent>
        <child>rleg1_ax1_link</child>
        <axis>
          <xyz>0 0 -1</xyz>
          <limit>
            <lower>-1.5708</lower>
            <upper>1.5708</upper>
            <effort>30</effort>
            <velocity>1</velocity>
          </limit>
          <dynamics>
            <damping>10</damping>
            <friction>50</friction>
            <spring_reference>0</spring_reference>
            <spring_stiffness>0</spring_stiffness>
          </dynamics>
        </axis>
      </joint>
      <link name='rleg1_ax1_link'>
        <pose relative_to='rleg1_ax1_joint'>0 0 0 0 -0 0</pose>
        <inertial>
          <pose>0 0 0 0 -0 0</pose>
          <mass>5</mass>
          <inertia>
            <ixx>0.00483333</ixx>
            <ixy>0</ixy>
            <ixz>0</ixz>
            <iyy>0.00483333</iyy>
            <iyz>0</iyz>
            <izz>0.00133333</izz>
          </inertia>
        </inertial>
        <collision name='rleg1_ax1_link_collision'>
          <pose>0 0 -0.03 0 -0 0</pose>
          <geometry>
            <box>
              <size>0.04 0.04 0.1</size>
            </box>
          </geometry>
          <surface>
            <contact>
              <ode/>
            </contact>
            <friction>
              <ode>
                <mu>50</mu>
                <mu2>50</mu2>
              </ode>
              <torsional>
                <ode/>
              </torsional>
            </friction>
            <bounce/>
          </surface>
          <max_contacts>10</max_contacts>
        </collision>
        <visual name='rleg1_ax1_link_visual'>
          <pose>0 0 -0.03 0 -0 0</pose>
          <geometry>
            <box>
              <size>0.04 0.04 0.1</size>
            </box>
          </geometry>
          <material>
            <script>
              <name>Gazebo/Black</name>
              <uri>file://media/materials/scripts/gazebo.material</uri>
            </script>
          </material>
        </visual>
        <self_collide>0</self_collide>
        <enable_wind>0</enable_wind>
        <kinematic>0</kinematic>
      </link>
      <joint name='rleg1_ax2_joint' type='revolute'>
        <pose relative_to='rleg1_ax1_link'>0 0.04 0 0 -0 0</pose>
        <parent>rleg1_ax1_link</parent>
        <child>rleg1_ax2_link</child>
        <axis>
          <xyz>0 -1 0</xyz>
          <limit>
            <lower>-1.5708</lower>
            <upper>1.5708</upper>
            <effort>30</effort>
            <velocity>1</velocity>
          </limit>
          <dynamics>
            <damping>10</damping>
            <friction>50</friction>
            <spring_reference>0</spring_reference>
            <spring_stiffness>0</spring_stiffness>
          </dynamics>
        </axis>
      </joint>
      <link name='rleg1_ax2_link'>
        <pose relative_to='rleg1_ax2_joint'>0 0 0 0 -0 0</pose>
        <inertial>
          <pose>0 0 0 0 -0 0</pose>
          <mass>5</mass>
          <inertia>
            <ixx>0.0673333</ixx>
            <ixy>0</ixy>
            <ixz>0</ixz>
            <iyy>0.0673333</iyy>
            <iyz>0</iyz>
            <izz>0.00133333</izz>
          </inertia>
        </inertial>
        <collision name='rleg1_ax2_link_collision'>
          <pose>0 0 0.18 0 -0 0</pose>
          <geometry>
            <box>
              <size>0.04 0.04 0.4</size>
            </box>
          </geometry>
          <surface>
            <contact>
              <ode/>
            </contact>
            <friction>
              <ode>
                <mu>50</mu>
                <mu2>50</mu2>
              </ode>
              <torsional>
                <ode/>
              </torsional>
            </friction>
            <bounce/>
          </surface>
          <max_contacts>10</max_contacts>
        </collision>
        <visual name='rleg1_ax2_link_visual'>
          <pose>0 0 0.18 0 -0 0</pose>
          <geometry>
            <box>
              <size>0.04 0.04 0.4</size>
            </box>
          </geometry>
          <material>
            <script>
              <name>Gazebo/Red</name>
              <uri>file://media/materials/scripts/gazebo.material</uri>
            </script>
          </material>
        </visual>
        <self_collide>0</self_collide>
        <enable_wind>0</enable_wind>
        <kinematic>0</kinematic>
      </link>
      <joint name='rleg1_ax3_joint' type='revolute'>
        <pose relative_to='rleg1_ax2_link'>0 0 0.36 0 -0 0</pose>
        <parent>rleg1_ax2_link</parent>
        <child>rleg1_ax3_link</child>
        <axis>
          <xyz>0 -1 0</xyz>
          <limit>
            <lower>-3.14159</lower>
            <upper>3.14159</upper>
            <effort>30</effort>
            <velocity>1</velocity>
          </limit>
          <dynamics>
            <damping>10</damping>
            <friction>50</friction>
            <spring_reference>0</spring_reference>
            <spring_stiffness>0</spring_stiffness>
          </dynamics>
        </axis>
      </joint>
      <link name='rleg1_ax3_link'>
        <pose relative_to='rleg1_ax3_joint'>0 0 0 0 -0 0</pose>
        <inertial>
          <pose>0 0 0 0 -0 0</pose>
          <mass>5</mass>
          <inertia>
            <ixx>0.0673333</ixx>
            <ixy>0</ixy>
            <ixz>0</ixz>
            <iyy>0.0673333</iyy>
            <iyz>0</iyz>
            <izz>0.00133333</izz>
          </inertia>
        </inertial>
        <collision name='rleg1_ax3_link_collision'>
          <pose>0 -0.04 0.18 0 -0 0</pose>
          <geometry>
            <box>
              <size>0.04 0.04 0.4</size>
            </box>
          </geometry>
          <surface>
            <contact>
              <ode/>
            </contact>
            <friction>
              <ode>
                <mu>50</mu>
                <mu2>50</mu2>
                <fdir1>1 0 0</fdir1>
              </ode>
              <torsional>
                <ode/>
              </torsional>
            </friction>
            <bounce/>
          </surface>
          <max_contacts>10</max_contacts>
        </collision>
        <collision name='rleg1_ax3_link_collision_1'>
          <pose>0 -0.04 0.38 0 -0 0</pose>
          <geometry>
            <sphere>
              <radius>0.04</radius>
            </sphere>
          </geometry>
          <surface>
            <contact>
              <ode/>
            </contact>
            <friction>
              <ode>
                <mu>50</mu>
                <mu2>50</mu2>
                <fdir1>1 0 0</fdir1>
              </ode>
              <torsional>
                <ode/>
              </torsional>
            </friction>
            <bounce/>
          </surface>
          <max_contacts>10</max_contacts>
        </collision>
        <visual name='rleg1_ax3_link_visual'>
          <pose>0 -0.04 0.18 0 -0 0</pose>
          <geometry>
            <box>
              <size>0.04 0.04 0.4</size>
            </box>
          </geometry>
          <material>
            <script>
              <name>Gazebo/Black</name>
              <uri>file://media/materials/scripts/gazebo.material</uri>
            </script>
          </material>
        </visual>
        <visual name='rleg1_ax3_link_visual_1'>
          <pose>0 -0.04 0.38 0 -0 0</pose>
          <geometry>
            <sphere>
              <radius>0.04</radius>
            </sphere>
          </geometry>
          <material>
            <script>
              <name>Gazebo/Black</name>
              <uri>file://media/materials/scripts/gazebo.material</uri>
            </script>
          </material>
        </visual>
        <self_collide>0</self_collide>
        <enable_wind>0</enable_wind>
        <kinematic>0</kinematic>
      </link>
      <joint name='rleg2_ax1_joint' type='revolute'>
        <pose relative_to='base_link'>-0.22 -0.22 0.12 0 -0 0</pose>
        <parent>base_link</parent>
        <child>rleg2_ax1_link</child>
        <axis>
          <xyz>0 0 -1</xyz>
          <limit>
            <lower>-1.5708</lower>
            <upper>1.5708</upper>
            <effort>30</effort>
            <velocity>1</velocity>
          </limit>
          <dynamics>
            <damping>10</damping>
            <friction>50</friction>
            <spring_reference>0</spring_reference>
            <spring_stiffness>0</spring_stiffness>
          </dynamics>
        </axis>
      </joint>
      <link name='rleg2_ax1_link'>
        <pose relative_to='rleg2_ax1_joint'>0 0 0 0 -0 0</pose>
        <inertial>
          <pose>0 0 0 0 -0 0</pose>
          <mass>5</mass>
          <inertia>
            <ixx>0.00483333</ixx>
            <ixy>0</ixy>
            <ixz>0</ixz>
            <iyy>0.00483333</iyy>
            <iyz>0</iyz>
            <izz>0.00133333</izz>
          </inertia>
        </inertial>
        <collision name='rleg2_ax1_link_collision'>
          <pose>0 0 -0.03 0 -0 0</pose>
          <geometry>
            <box>
              <size>0.04 0.04 0.1</size>
            </box>
          </geometry>
          <surface>
            <contact>
              <ode/>
            </contact>
            <friction>
              <ode>
                <mu>50</mu>
                <mu2>50</mu2>
              </ode>
              <torsional>
                <ode/>
              </torsional>
            </friction>
            <bounce/>
          </surface>
          <max_contacts>10</max_contacts>
        </collision>
        <visual name='rleg2_ax1_link_visual'>
          <pose>0 0 -0.03 0 -0 0</pose>
          <geometry>
            <box>
              <size>0.04 0.04 0.1</size>
            </box>
          </geometry>
          <material>
            <script>
              <name>Gazebo/Black</name>
              <uri>file://media/materials/scripts/gazebo.material</uri>
            </script>
          </material>
        </visual>
        <self_collide>0</self_collide>
        <enable_wind>0</enable_wind>
        <kinematic>0</kinematic>
      </link>
      <joint name='rleg2_ax2_joint' type='revolute'>
        <pose relative_to='rleg2_ax1_link'>0 0.04 0 0 -0 0</pose>
        <parent>rleg2_ax1_link</parent>
        <child>rleg2_ax2_link</child>
        <axis>
          <xyz>0 -1 0</xyz>
          <limit>
            <lower>-1.5708</lower>
            <upper>1.5708</upper>
            <effort>30</effort>
            <velocity>1</velocity>
          </limit>
          <dynamics>
            <damping>10</damping>
            <friction>50</friction>
            <spring_reference>0</spring_reference>
            <spring_stiffness>0</spring_stiffness>
          </dynamics>
        </axis>
      </joint>
      <link name='rleg2_ax2_link'>
        <pose relative_to='rleg2_ax2_joint'>0 0 0 0 -0 0</pose>
        <inertial>
          <pose>0 0 0 0 -0 0</pose>
          <mass>5</mass>
          <inertia>
            <ixx>0.0673333</ixx>
            <ixy>0</ixy>
            <ixz>0</ixz>
            <iyy>0.0673333</iyy>
            <iyz>0</iyz>
            <izz>0.00133333</izz>
          </inertia>
        </inertial>
        <collision name='rleg2_ax2_link_collision'>
          <pose>0 0 0.18 0 -0 0</pose>
          <geometry>
            <box>
              <size>0.04 0.04 0.4</size>
            </box>
          </geometry>
          <surface>
            <contact>
              <ode/>
            </contact>
            <friction>
              <ode>
                <mu>50</mu>
                <mu2>50</mu2>
              </ode>
              <torsional>
                <ode/>
              </torsional>
            </friction>
            <bounce/>
          </surface>
          <max_contacts>10</max_contacts>
        </collision>
        <visual name='rleg2_ax2_link_visual'>
          <pose>0 0 0.18 0 -0 0</pose>
          <geometry>
            <box>
              <size>0.04 0.04 0.4</size>
            </box>
          </geometry>
          <material>
            <script>
              <name>Gazebo/Red</name>
              <uri>file://media/materials/scripts/gazebo.material</uri>
            </script>
          </material>
        </visual>
        <self_collide>0</self_collide>
        <enable_wind>0</enable_wind>
        <kinematic>0</kinematic>
      </link>
      <joint name='rleg2_ax3_joint' type='revolute'>
        <pose relative_to='rleg2_ax2_link'>0 0 0.36 0 -0 0</pose>
        <parent>rleg2_ax2_link</parent>
        <child>rleg2_ax3_link</child>
        <axis>
          <xyz>0 -1 0</xyz>
          <limit>
            <lower>-3.14159</lower>
            <upper>3.14159</upper>
            <effort>30</effort>
            <velocity>1</velocity>
          </limit>
          <dynamics>
            <damping>10</damping>
            <friction>50</friction>
            <spring_reference>0</spring_reference>
            <spring_stiffness>0</spring_stiffness>
          </dynamics>
        </axis>
      </joint>
      <link name='rleg2_ax3_link'>
        <pose relative_to='rleg2_ax3_joint'>0 0 0 0 -0 0</pose>
        <inertial>
          <pose>0 0 0 0 -0 0</pose>
          <mass>5</mass>
          <inertia>
            <ixx>0.0673333</ixx>
            <ixy>0</ixy>
            <ixz>0</ixz>
            <iyy>0.0673333</iyy>
            <iyz>0</iyz>
            <izz>0.00133333</izz>
          </inertia>
        </inertial>
        <collision name='rleg2_ax3_link_collision'>
          <pose>0 -0.04 0.18 0 -0 0</pose>
          <geometry>
            <box>
              <size>0.04 0.04 0.4</size>
            </box>
          </geometry>
          <surface>
            <contact>
              <ode/>
            </contact>
            <friction>
              <ode>
                <mu>50</mu>
                <mu2>50</mu2>
                <fdir1>1 0 0</fdir1>
              </ode>
              <torsional>
                <ode/>
              </torsional>
            </friction>
            <bounce/>
          </surface>
          <max_contacts>10</max_contacts>
        </collision>
        <collision name='rleg2_ax3_link_collision_1'>
          <pose>0 -0.04 0.38 0 -0 0</pose>
          <geometry>
            <sphere>
              <radius>0.04</radius>
            </sphere>
          </geometry>
          <surface>
            <contact>
              <ode/>
            </contact>
            <friction>
              <ode>
                <mu>50</mu>
                <mu2>50</mu2>
                <fdir1>1 0 0</fdir1>
              </ode>
              <torsional>
                <ode/>
              </torsional>
            </friction>
            <bounce/>
          </surface>
          <max_contacts>10</max_contacts>
        </collision>
        <visual name='rleg2_ax3_link_visual'>
          <pose>0 -0.04 0.18 0 -0 0</pose>
          <geometry>
            <box>
              <size>0.04 0.04 0.4</size>
            </box>
          </geometry>
          <material>
            <script>
              <name>Gazebo/Black</name>
              <uri>file://media/materials/scripts/gazebo.material</uri>
            </script>
          </material>
        </visual>
        <visual name='rleg2_ax3_link_visual_1'>
          <pose>0 -0.04 0.38 0 -0 0</pose>
          <geometry>
            <sphere>
              <radius>0.04</radius>
            </sphere>
          </geometry>
          <material>
            <script>
              <name>Gazebo/Black</name>
              <uri>file://media/materials/scripts/gazebo.material</uri>
            </script>
          </material>
        </visual>
        <self_collide>0</self_collide>
        <enable_wind>0</enable_wind>
        <kinematic>0</kinematic>
      </link>
      <static>0</static>
      <plugin name='gazebo_ros2_control' filename='libgazebo_ros2_control.so'>
        <parameters>/home/vel/ros2_ws/install/spyderbot/share/spyderbot/config/controller_position.yaml</parameters>
      </plugin>
      <pose>0 0 0 0 -0 0</pose>
    </model>
    <state world_name='default'>
      <sim_time>162 348000000</sim_time>
      <real_time>164 999184653</real_time>
      <wall_time>1663480161 190321382</wall_time>
      <iterations>162348</iterations>
      <model name='ground_plane'>
        <pose>0 0 0 0 -0 0</pose>
        <scale>1 1 1</scale>
        <link name='link'>
          <pose>0 0 0 0 -0 0</pose>
          <velocity>0 0 0 0 -0 0</velocity>
          <acceleration>0 0 0 0 -0 0</acceleration>
          <wrench>0 0 0 0 -0 0</wrench>
        </link>
      </model>
      <model name='my_bot'>
        <pose>-0.467756 -2.76872 0.118654 -4.1e-05 2.7e-05 -0.222996</pose>
        <scale>1 1 1</scale>
        <link name='base_link'>
          <pose>-0.467756 -2.76872 0.118654 -4.1e-05 2.7e-05 -0.222996</pose>
          <velocity>0.002689 0.000972 -0.003605 -0.000574 0.001552 -0.000817</velocity>
          <acceleration>-0 0 0 2e-06 1e-06 0</acceleration>
          <wrench>-1e-06 4e-06 0 0 -0 0</wrench>
        </link>
        <link name='lleg1_ax1_link'>
          <pose>-0.204546 -2.60282 0.238639 -5.2e-05 4.8e-05 0.562403</pose>
          <velocity>0.002927 0.000782 -0.004152 0.015867 -0.014623 -0.001564</velocity>
          <acceleration>-0 0 -0 -3.3e-05 -0.000264 0.002344</acceleration>
          <wrench>-1e-06 2e-06 -0 0 -0 0</wrench>
        </link>
        <link name='lleg1_ax2_link'>
          <pose>-0.225876 -2.56898 0.238638 -0.000433 1.11869 0.561956</pose>
          <velocity>0.002451 0.000447 -0.003849 0.027212 -0.017215 -0.007709</velocity>
          <acceleration>-0 0 -0 -0.04627 -0.0293 -0.026349</acceleration>
          <wrench>-0 2e-06 -0 0 -0 0</wrench>
        </link>
        <link name='lleg1_ax3_link'>
          <pose>0.048071 -2.3963 0.395907 -3.14134 0.357936 -2.57919</pose>
          <velocity>0.000284 -0.006323 0.006446 0.039744 0.009866 -0.072224</velocity>
          <acceleration>1e-06 0 0 -0.012015 -0.006508 0.040272</acceleration>
          <wrench>4e-06 0 0 0 -0 0</wrench>
        </link>
        <link name='lleg2_ax1_link'>
          <pose>-0.301853 -3.03192 0.238657 -6.7e-05 -0.000116 -1.0084</pose>
          <velocity>0.002744 0.001008 -0.003718 -0.005834 -0.000971 -0.004016</velocity>
          <acceleration>-0 0 0 9.7e-05 -0.002342 0.003586</acceleration>
          <wrench>-1e-06 2e-06 0 0 -0 0</wrench>
        </link>
        <link name='lleg2_ax2_link'>
          <pose>-0.268015 -3.01059 0.238655 -0.000348 1.11881 -1.00878</pose>
          <velocity>0.00289 0.000961 -0.003781 -0.014732 -0.005416 -0.00445</velocity>
          <acceleration>-0 0 0 -0.181906 0.288625 -0.162358</acceleration>
          <wrench>-1e-06 2e-06 0 0 -0 0</wrench>
        </link>
        <link name='lleg2_ax3_link'>
          <pose>-0.095335 -3.28456 0.39589 -3.14144 0.358084 2.13303</pose>
          <velocity>0.000709 0.002611 0.001325 -0.005084 -0.003903 -0.015346</velocity>
          <acceleration>-0 0 0 -0.001872 0.002845 0.009577</acceleration>
          <wrench>-2e-06 1e-06 0 0 -0 0</wrench>
        </link>
        <link name='rleg1_ax1_link'>
          <pose>-0.633651 -2.50551 0.238652 -6.7e-05 0.000123 -1.00839</pose>
          <velocity>0.003236 0.001226 -0.003549 0.003292 0.005108 0.004392</velocity>
          <acceleration>-0 0 0 0.003476 -0.001958 -0.004159</acceleration>
          <wrench>-1e-06 2e-06 0 0 -0 0</wrench>
        </link>
        <link name='rleg1_ax2_link'>
          <pose>-0.599811 -2.48418 0.23865 -0.000373 -1.1188 -1.00798</pose>
          <velocity>0.003211 0.001317 -0.003643 0.012686 0.011729 0.005474</velocity>
          <acceleration>-0 0 0 -0.166438 0.264028 0.148683</acceleration>
          <wrench>-1e-06 2e-06 0 0 -0 0</wrench>
        </link>
        <link name='rleg1_ax3_link'>
          <pose>-0.772491 -2.21022 0.395888 -3.14143 -0.358094 2.13336</pose>
          <velocity>0.00365 -0.001677 0.001938 0.007044 0.005452 0.012571</velocity>
          <acceleration>0 0 0 -0.001789 0.002944 -0.009702</acceleration>
          <wrench>1e-06 2e-06 0 0 -0 0</wrench>
        </link>
        <link name='rleg2_ax1_link'>
          <pose>-0.730957 -2.93461 0.238669 -1.7e-05 4.9e-05 0.5624</pose>
          <velocity>0.002711 0.001233 -0.003021 -0.003306 0.006515 -0.001174</velocity>
          <acceleration>-0 0 0 -7e-05 -8.1e-05 -0.00155</acceleration>
          <wrench>-1e-06 2e-06 0 0 -0 0</wrench>
        </link>
        <link name='rleg2_ax2_link'>
          <pose>-0.752281 -2.90077 0.238669 -6.8e-05 -1.11884 0.562487</pose>
          <velocity>0.002491 0.001066 -0.002959 -0.012021 0.021452 0.001129</velocity>
          <acceleration>-0 0 0 0.573952 -1.52317 -1.70324</acceleration>
          <wrench>-0 2e-06 0 0 -0 0</wrench>
        </link>
        <link name='rleg2_ax3_link'>
          <pose>-1.02624 -3.07345 0.3959 3.14153 -0.358033 -2.57846</pose>
          <velocity>0.005435 0.002224 0.004749 -0.015791 -0.000923 -0.051019</velocity>
          <acceleration>-0 1e-06 0 0.00336 0.002418 0.012449</acceleration>
          <wrench>-2e-06 4e-06 0 0 -0 0</wrench>
        </link>
      </model>
      <light name='sun'>
        <pose>0 0 10 0 -0 0</pose>
      </light>
    </state>
    <gui fullscreen='0'>
      <camera name='user_camera'>
        <pose>5 -5 2 0 0.275643 2.35619</pose>
        <view_controller>orbit</view_controller>
        <projection_type>perspective</projection_type>
      </camera>
    </gui>
  </world>
</sdf>
